{
  "comments": [
    {
      "unresolved": false,
      "key": {
        "uuid": "601c9920_d54acc9e",
        "filename": "/PATCHSET_LEVEL",
        "patchSetId": 5
      },
      "lineNbr": 0,
      "author": {
        "id": 1000469
      },
      "writtenOn": "2024-06-12T11:28:46Z",
      "side": 1,
      "message": "Only issue I had was with python3-markdown 3.4.4-1 at 23.10 ubuntu.\nbut build requires older version\nERROR: pip\u0027s dependency resolver does not currently take into account all the packages that are installed. This behavior is the source of the following dependency conflicts.\nmkdocs 1.4.2 requires markdown\u003c3.4,\u003e\u003d3.2.1, but you have markdown 3.4.4 which is incompatible.",
      "revId": "4f896617bf5102c4f58494afe26ed253481c48d8",
      "serverId": "8f6f209b-db1a-4cbf-aa44-c8bc30e9bfda"
    },
    {
      "unresolved": false,
      "key": {
        "uuid": "d3a7b6e8_21fdce67",
        "filename": "/PATCHSET_LEVEL",
        "patchSetId": 5
      },
      "lineNbr": 0,
      "author": {
        "id": 1000744
      },
      "writtenOn": "2024-06-13T17:23:36Z",
      "side": 1,
      "message": "Hi Michal, thanks for the feedback! I was unable to reproduce the installation errors you\u0027re referring to. Did you install using the requirements.txt file? The easiest way to get setup is to run `make -C tools/tlc install`. In future we will deploy this package to pypi, which should simplify the installation process.",
      "parentUuid": "601c9920_d54acc9e",
      "revId": "4f896617bf5102c4f58494afe26ed253481c48d8",
      "serverId": "8f6f209b-db1a-4cbf-aa44-c8bc30e9bfda"
    },
    {
      "unresolved": false,
      "key": {
        "uuid": "c0fd7635_ce7ee61e",
        "filename": "/PATCHSET_LEVEL",
        "patchSetId": 5
      },
      "lineNbr": 0,
      "author": {
        "id": 1000744
      },
      "writtenOn": "2024-06-13T17:24:03Z",
      "side": 1,
      "message": "https://github.com/FirmwareHandoff/firmware_handoff/pull/45",
      "parentUuid": "601c9920_d54acc9e",
      "revId": "4f896617bf5102c4f58494afe26ed253481c48d8",
      "serverId": "8f6f209b-db1a-4cbf-aa44-c8bc30e9bfda"
    },
    {
      "unresolved": true,
      "key": {
        "uuid": "7ace7142_9097b2d4",
        "filename": "tools/tlc/tlc/tl.py",
        "patchSetId": 5
      },
      "lineNbr": 130,
      "author": {
        "id": 1000469
      },
      "writtenOn": "2024-06-12T11:21:18Z",
      "side": 1,
      "message": "I tried to add --fdt with getting to this error. By default you have 1000bytes and if DT is bigger (which is almost always the case) you get error from python but it is not clear what to do. Would be better to handle it and let recommendation to user to increase size via -s.",
      "revId": "4f896617bf5102c4f58494afe26ed253481c48d8",
      "serverId": "8f6f209b-db1a-4cbf-aa44-c8bc30e9bfda"
    },
    {
      "unresolved": false,
      "key": {
        "uuid": "1fbde8ac_326b84d5",
        "filename": "tools/tlc/tlc/tl.py",
        "patchSetId": 5
      },
      "lineNbr": 130,
      "author": {
        "id": 1000744
      },
      "writtenOn": "2024-06-13T17:23:36Z",
      "side": 1,
      "message": "Done",
      "parentUuid": "7ace7142_9097b2d4",
      "revId": "4f896617bf5102c4f58494afe26ed253481c48d8",
      "serverId": "8f6f209b-db1a-4cbf-aa44-c8bc30e9bfda"
    }
  ]
}